[0m21:13:40.160061 [debug] [MainThread]: Sending event: {'category': 'dbt', 'action': 'invocation', 'label': 'start', 'context': [<snowplow_tracker.self_describing_json.SelfDescribingJson object at 0x7c4435d57da0>, <snowplow_tracker.self_describing_json.SelfDescribingJson object at 0x7c44351b7ef0>, <snowplow_tracker.self_describing_json.SelfDescribingJson object at 0x7c443648fc80>]}


============================== 21:13:40.169029 | ba3cee6b-039c-47ba-8c81-3751a7fada95 ==============================
[0m21:13:40.169029 [info ] [MainThread]: Running with dbt=1.8.2
[0m21:13:40.170242 [debug] [MainThread]: running dbt with arguments {'printer_width': '80', 'indirect_selection': 'eager', 'log_cache_events': 'False', 'write_json': 'True', 'partial_parse': 'True', 'cache_selected_only': 'False', 'profiles_dir': '/home/monica/.dbt', 'debug': 'False', 'warn_error': 'None', 'log_path': 'logs', 'fail_fast': 'False', 'version_check': 'True', 'use_colors': 'True', 'use_experimental_parser': 'False', 'no_print': 'None', 'quiet': 'False', 'warn_error_options': 'WarnErrorOptions(include=[], exclude=[])', 'introspect': 'True', 'invocation_command': 'dbt init', 'log_format': 'default', 'target_path': 'None', 'static_parser': 'True', 'send_anonymous_usage_stats': 'True'}
[0m21:13:40.186082 [warn ] [MainThread]: [ConfigFolderDirectory]: Unable to parse dict {'dir': PosixPath('/home/monica/.dbt')}
[0m21:13:40.186983 [info ] [MainThread]: Creating dbt configuration folder at 
[0m21:32:59.213115 [debug] [MainThread]: Starter project path: /home/monica/Documentos/MÃ´nica/projetodw/.venv/lib/python3.12/site-packages/dbt/include/starter_project
[0m21:32:59.216521 [info ] [MainThread]: 
Your new dbt project "exit" was created!

For more information on how to configure the profiles.yml file,
please consult the dbt documentation here:

  https://docs.getdbt.com/docs/configure-your-profile

One more thing:

Need help? Don't hesitate to reach out to us via GitHub issues or on Slack:

  https://community.getdbt.com/

Happy modeling!

[0m21:32:59.217499 [info ] [MainThread]: Setting up your profile.
[0m21:40:31.474709 [debug] [MainThread]: Sending event: {'category': 'dbt', 'action': 'invocation', 'label': 'start', 'context': [<snowplow_tracker.self_describing_json.SelfDescribingJson object at 0x717c46f6bc20>, <snowplow_tracker.self_describing_json.SelfDescribingJson object at 0x717c4650f3b0>, <snowplow_tracker.self_describing_json.SelfDescribingJson object at 0x717c4653bd70>]}


============================== 21:40:31.479295 | 1452a5d3-ce00-48cf-8b9b-7eab01207624 ==============================
[0m21:40:31.479295 [info ] [MainThread]: Running with dbt=1.8.2
[0m21:40:31.480021 [debug] [MainThread]: running dbt with arguments {'printer_width': '80', 'indirect_selection': 'eager', 'write_json': 'True', 'log_cache_events': 'False', 'partial_parse': 'True', 'cache_selected_only': 'False', 'warn_error': 'None', 'fail_fast': 'False', 'profiles_dir': '/home/monica/.dbt', 'log_path': 'logs', 'debug': 'False', 'version_check': 'True', 'use_colors': 'True', 'use_experimental_parser': 'False', 'no_print': 'None', 'quiet': 'False', 'warn_error_options': 'WarnErrorOptions(include=[], exclude=[])', 'introspect': 'True', 'invocation_command': 'dbt init', 'static_parser': 'True', 'target_path': 'None', 'log_format': 'default', 'send_anonymous_usage_stats': 'True'}
[0m21:42:20.420338 [debug] [MainThread]: Starter project path: /home/monica/Documentos/MÃ´nica/projetodw/.venv/lib/python3.12/site-packages/dbt/include/starter_project
[0m21:42:20.424162 [info ] [MainThread]: 
Your new dbt project "datawarehouse" was created!

For more information on how to configure the profiles.yml file,
please consult the dbt documentation here:

  https://docs.getdbt.com/docs/configure-your-profile

One more thing:

Need help? Don't hesitate to reach out to us via GitHub issues or on Slack:

  https://community.getdbt.com/

Happy modeling!

[0m21:42:20.424864 [info ] [MainThread]: Setting up your profile.
[0m21:42:44.151012 [error] [MainThread]: Encountered an error:
libpq.so.5: cannot open shared object file: No such file or directory
[0m21:42:44.153573 [error] [MainThread]: Traceback (most recent call last):
  File "/home/monica/Documentos/MÃ´nica/projetodw/.venv/lib/python3.12/site-packages/dbt/cli/requires.py", line 138, in wrapper
    result, success = func(*args, **kwargs)
                      ^^^^^^^^^^^^^^^^^^^^^
  File "/home/monica/Documentos/MÃ´nica/projetodw/.venv/lib/python3.12/site-packages/dbt/cli/requires.py", line 101, in wrapper
    return func(*args, **kwargs)
           ^^^^^^^^^^^^^^^^^^^^^
  File "/home/monica/Documentos/MÃ´nica/projetodw/.venv/lib/python3.12/site-packages/dbt/cli/main.py", line 470, in init
    results = task.run()
              ^^^^^^^^^^
  File "/home/monica/Documentos/MÃ´nica/projetodw/.venv/lib/python3.12/site-packages/dbt/task/init.py", line 347, in run
    self.setup_profile(profile_name)
  File "/home/monica/Documentos/MÃ´nica/projetodw/.venv/lib/python3.12/site-packages/dbt/task/init.py", line 263, in setup_profile
    self.create_profile_from_target(adapter, profile_name=profile_name)
  File "/home/monica/Documentos/MÃ´nica/projetodw/.venv/lib/python3.12/site-packages/dbt/task/init.py", line 173, in create_profile_from_target
    load_plugin(adapter)
  File "/home/monica/Documentos/MÃ´nica/projetodw/.venv/lib/python3.12/site-packages/dbt/adapters/factory.py", line 239, in load_plugin
    return FACTORY.load_plugin(name)
           ^^^^^^^^^^^^^^^^^^^^^^^^^
  File "/home/monica/Documentos/MÃ´nica/projetodw/.venv/lib/python3.12/site-packages/dbt/adapters/factory.py", line 68, in load_plugin
    mod: Any = import_module("." + name, "dbt.adapters")
               ^^^^^^^^^^^^^^^^^^^^^^^^^^^^^^^^^^^^^^^^^
  File "/home/monica/.pyenv/versions/3.12.4/lib/python3.12/importlib/__init__.py", line 90, in import_module
    return _bootstrap._gcd_import(name[level:], package, level)
           ^^^^^^^^^^^^^^^^^^^^^^^^^^^^^^^^^^^^^^^^^^^^^^^^^^^^
  File "<frozen importlib._bootstrap>", line 1387, in _gcd_import
  File "<frozen importlib._bootstrap>", line 1360, in _find_and_load
  File "<frozen importlib._bootstrap>", line 1331, in _find_and_load_unlocked
  File "<frozen importlib._bootstrap>", line 935, in _load_unlocked
  File "<frozen importlib._bootstrap_external>", line 995, in exec_module
  File "<frozen importlib._bootstrap>", line 488, in _call_with_frames_removed
  File "/home/monica/Documentos/MÃ´nica/projetodw/.venv/lib/python3.12/site-packages/dbt/adapters/postgres/__init__.py", line 4, in <module>
    from dbt.adapters.postgres.connections import PostgresConnectionManager, PostgresCredentials
  File "/home/monica/Documentos/MÃ´nica/projetodw/.venv/lib/python3.12/site-packages/dbt/adapters/postgres/connections.py", line 13, in <module>
    import psycopg2
  File "/home/monica/Documentos/MÃ´nica/projetodw/.venv/lib/python3.12/site-packages/psycopg2/__init__.py", line 51, in <module>
    from psycopg2._psycopg import (                     # noqa
ImportError: libpq.so.5: cannot open shared object file: No such file or directory

[0m21:42:44.154716 [debug] [MainThread]: Resource report: {"command_name": "init", "command_wall_clock_time": 132.73099, "process_user_time": 1.293681, "process_kernel_time": 0.134758, "process_mem_max_rss": "88588", "process_out_blocks": "88", "command_success": false, "process_in_blocks": "0"}
[0m21:42:44.155361 [debug] [MainThread]: Command `dbt init` failed at 21:42:44.155266 after 132.73 seconds
[0m21:42:44.155805 [debug] [MainThread]: Sending event: {'category': 'dbt', 'action': 'invocation', 'label': 'end', 'context': [<snowplow_tracker.self_describing_json.SelfDescribingJson object at 0x717c465503b0>, <snowplow_tracker.self_describing_json.SelfDescribingJson object at 0x717c46b77b00>, <snowplow_tracker.self_describing_json.SelfDescribingJson object at 0x717c4653a0f0>]}
[0m21:42:44.156236 [debug] [MainThread]: Flushing usage events
